<?xml version="1.0" encoding="UTF-8"?>
<!-- Generated by org.testng.reporters.JUnitXMLReporter -->
<testsuite ignored="6" hostname="LAPTOP-PL6FGJN7" failures="1" tests="1" name="Default test" time="14.48" errors="0" timestamp="2025-08-04T12:13:29 IST">
  <testcase classname="testCases.TC001_PurchaseFlow_Test" name="Verify_Invalid_Login_Fun" time="11.384">
    <failure type="java.lang.AssertionError" message="Expected login to fail with invalid credentials, but it passed. expected [true] but found [false]">
      <![CDATA[java.lang.AssertionError: Expected login to fail with invalid credentials, but it passed. expected [true] but found [false]
at org.testng.Assert.fail(Assert.java:111)
at org.testng.Assert.failNotEquals(Assert.java:1590)
at org.testng.Assert.assertEqualsImpl(Assert.java:150)
at org.testng.Assert.assertEquals(Assert.java:132)
at org.testng.Assert.assertEquals(Assert.java:1079)
at org.testng.Assert.assertEquals(Assert.java:1043)
at testCases.TC001_PurchaseFlow_Test.Verify_Invalid_Login_Fun(TC001_PurchaseFlow_Test.java:124)
at java.base/jdk.internal.reflect.DirectMethodHandleAccessor.invoke(DirectMethodHandleAccessor.java:104)
at java.base/java.lang.reflect.Method.invoke(Method.java:578)
at org.testng.internal.invokers.MethodInvocationHelper.invokeMethod(MethodInvocationHelper.java:141)
at org.testng.internal.invokers.TestInvoker.invokeMethod(TestInvoker.java:687)
at org.testng.internal.invokers.TestInvoker.invokeTestMethod(TestInvoker.java:230)
at org.testng.internal.invokers.MethodRunner.runInSequence(MethodRunner.java:63)
at org.testng.internal.invokers.TestInvoker$MethodInvocationAgent.invoke(TestInvoker.java:995)
at org.testng.internal.invokers.TestInvoker.invokeTestMethods(TestInvoker.java:203)
at org.testng.internal.invokers.TestMethodWorker.invokeTestMethods(TestMethodWorker.java:154)
at org.testng.internal.invokers.TestMethodWorker.run(TestMethodWorker.java:134)
at java.base/java.util.ArrayList.forEach(ArrayList.java:1511)
at org.testng.TestRunner.privateRun(TestRunner.java:741)
at org.testng.TestRunner.run(TestRunner.java:616)
at org.testng.SuiteRunner.runTest(SuiteRunner.java:421)
at org.testng.SuiteRunner.runSequentially(SuiteRunner.java:413)
at org.testng.SuiteRunner.privateRun(SuiteRunner.java:373)
at org.testng.SuiteRunner.run(SuiteRunner.java:312)
at org.testng.SuiteRunnerWorker.runSuite(SuiteRunnerWorker.java:52)
at org.testng.SuiteRunnerWorker.run(SuiteRunnerWorker.java:95)
at org.testng.TestNG.runSuitesSequentially(TestNG.java:1274)
at org.testng.TestNG.runSuitesLocally(TestNG.java:1208)
at org.testng.TestNG.runSuites(TestNG.java:1112)
at org.testng.TestNG.run(TestNG.java:1079)
at org.testng.remote.AbstractRemoteTestNG.run(AbstractRemoteTestNG.java:115)
at org.testng.remote.RemoteTestNG.initAndRun(RemoteTestNG.java:293)
at org.testng.remote.RemoteTestNG.main(RemoteTestNG.java:91)
]]>
    </failure>
  </testcase> <!-- Verify_Invalid_Login_Fun -->
  <testcase classname="testCases.TC001_PurchaseFlow_Test" name="Verify_CartPage_Func" time="0.0">
    <ignored/>
  </testcase> <!-- Verify_CartPage_Func -->
  <testcase classname="testCases.TC001_PurchaseFlow_Test" name="Verify_Logout_Fun" time="0.0">
    <ignored/>
  </testcase> <!-- Verify_Logout_Fun -->
  <testcase classname="testCases.TC001_PurchaseFlow_Test" name="Verify_Order_Success_Func" time="0.0">
    <ignored/>
  </testcase> <!-- Verify_Order_Success_Func -->
  <testcase classname="testCases.TC001_PurchaseFlow_Test" name="VerifyLoginFun" time="0.0">
    <ignored/>
  </testcase> <!-- VerifyLoginFun -->
  <testcase classname="testCases.TC001_PurchaseFlow_Test" name="VerifyAddToCartFunc" time="0.0">
    <ignored/>
  </testcase> <!-- VerifyAddToCartFunc -->
  <testcase classname="testCases.TC001_PurchaseFlow_Test" name="Verify_Checkout_Func" time="0.0">
    <ignored/>
  </testcase> <!-- Verify_Checkout_Func -->
</testsuite> <!-- Default test -->
